Workbook

Sheet Inputs
A1: AI Chatbot for University Student Support
A2: INPUT Data
A4: Parameter | B4: UC Berkeley | C4: Stanford University | D4: Arizona State University | F4: Enter your University: SJSU ( Example)
A6: SECTION 1 LABOR PARAMETERS
A7: Number of support staff (FTE) | B7: 12 | C7: 6 | D7: 25 | F7: 8
A8: Annual wage per employee ($) | B8: 54080 | C8: 62400 | D8: 43470 | F8: 62400
A9: Annual hours per FTE | B9: 2080 | C9: 2080 | D9: 2080 | F9: 2080
A10: Workforce reduction (base case %) | B10: 0.35 | C10: 0.35 | D10: 0.35 | F10: 0.35
A12: SECTION 2 YEAR 0 IMPLEMENTATION COSTS
A13: Initial setup / integration cost ($) | B13: 85000 | C13: 65000 | D13: 120000 | F13: 65000
A14: Staff training cost ($) | B14: 10000 | C14: 8000 | D14: 15000 | F14: 8000
A16: SECTION 3 ANNUAL RECURRING COSTS
A17: Annual chatbot subscription ($) | B17: 18000 | C17: 14400 | D17: 32400 | F17: 12000
A18: Annual maintenance / admin cost ($) | B18: 7000 | C18: 5500 | D18: 9000 | F18: 5500
A20: SECTION 4 GROWTH RATES & DISCOUNT RATE
A21: Annual benefit growth rate | B21: 0.03 | C21: 0.03 | D21: 0.03 | F21: 0.03
A22: Annual cost growth rate | B22: 0.04 | C22: 0.04 | D22: 0.04 | F22: 0.04
A23: Analysis period (years) | B23: 5 | C23: 5 | D23: 5 | F23: 5
A24: MARR / Discount rate | B24: 0.08 | C24: 0.08 | D24: 0.08 | F24: 0.08
A26: SECTION 5 Calculations
A27: Total labor cost (current, $/yr) | B27: =B7*B8 -> 648960 | C27: =C7*C8 -> 374400 | D27: =D7*D8 -> 1086750 | F27: =F7*F8 -> 499200
A28: Annual labor savings Year 1 ($) | B28: =B27*B10 -> 227136 | C28: =C27*C10 -> 131040 | D28: =D27*D10 -> 380362.5 | F28: =F27*F10 -> 174720
A29: Year 0 total investment ($) | B29: =B13+B14 -> 95000 | C29: =C13+C14 -> 73000 | D29: =D13+D14 -> 135000 | F29: =F13+F14 -> 73000
A30: Year 1 net cash flow ($) | B30: =B28-B17-B18 -> 202136 | C30: =C28-C17-C18 -> 111140 | D30: =D28-D17-D18 -> 338962.5 | F30: =F28-F17-F18 -> 157220

Sheet Cash Flows
A1: 5-YEAR CASH FLOW ANALYSIS | All Universities
A3: UC Berkeley
A4: University | B4: Year | C4: Labor Savings ($) | D4: Subscription ($) | E4: Maintenance ($) | F4: Net Cash Flow ($) | G4: Discount Factor | H4: PV of Cash Flow ($) | I4: Cumulative PV ($)
A5: UC Berkeley | B5: 0 | C5: 0 | D5: 0 | E5: 0 | F5: =-(Inputs!B13+Inputs!B14) -> -95000 | G5: 1 | H5: =F5*G5 -> -95000 | I5: =H5 -> -95000
B6: 1 | C6: =Inputs!B7*Inputs!B8*Inputs!B10 -> 227136 | D6: =Inputs!B17 -> 18000 | E6: =Inputs!B18 -> 7000 | F6: =C6-D6-E6 -> 202136 | G6: =1/(1+Inputs!B24)^B6 -> 0.92592593 | H6: =F6*G6 -> 187162.96 | I6: =I5+H6 -> 92162.963
B7: 2 | C7: =C6*(1+Inputs!B21) -> 233950.08 | D7: =D6*(1+Inputs!B22) -> 18720 | E7: =E6*(1+Inputs!B22) -> 7280 | F7: =C7-D7-E7 -> 207950.08 | G7: =1/(1+Inputs!B24)^B7 -> 0.85733882 | H7: =F7*G7 -> 178283.68 | I7: =I6+H7 -> 270446.64
B8: 3 | C8: =C7*(1+Inputs!B21) -> 240968.58 | D8: =D7*(1+Inputs!B22) -> 19468.8 | E8: =E7*(1+Inputs!B22) -> 7571.2 | F8: =C8-D8-E8 -> 213928.58 | G8: =1/(1+Inputs!B24)^B8 -> 0.79383224 | H8: =F8*G8 -> 169823.41 | I8: =I7+H8 -> 440270.05
B9: 4 | C9: =C8*(1+Inputs!B21) -> 248197.64 | D9: =D8*(1+Inputs!B22) -> 20247.552 | E9: =E8*(1+Inputs!B22) -> 7874.048 | F9: =C9-D9-E9 -> 220076.04 | G9: =1/(1+Inputs!B24)^B9 -> 0.73502985 | H9: =F9*G9 -> 161762.46 | I9: =I8+H9 -> 602032.5
B10: 5 | C10: =C9*(1+Inputs!B21) -> 255643.57 | D10: =D9*(1+Inputs!B22) -> 21057.454 | E10: =E9*(1+Inputs!B22) -> 8189.0099 | F10: =C10-D10-E10 -> 226397.11 | G10: =1/(1+Inputs!B24)^B10 -> 0.6805832 | H10: =F10*G10 -> 154082.07 | I10: =I9+H10 -> 756114.57
A11: TOTALS | C11: =SUM(C5:C10) -> 1205895.9 | D11: =SUM(D5:D10) -> 97493.806 | E11: =SUM(E5:E10) -> 37914.258 | F11: =SUM(F5:F10) -> 975487.81 | G11: =SUM(G5:G10) -> 4.99271 | H11: =SUM(H5:H10) -> 756114.57 | I11: =SUM(I5:I10) -> 2066026.7
A13: Stanford University
A14: University | B14: Year | C14: Labor Savings ($) | D14: Subscription ($) | E14: Maintenance ($) | F14: Net Cash Flow ($) | G14: Discount Factor | H14: PV of Cash Flow ($) | I14: Cumulative PV ($)
A15: Stanford University | B15: 0 | C15: 0 | D15: 0 | E15: 0 | F15: =-(Inputs!C13+Inputs!C14) -> -73000 | G15: 1 | H15: =F15*G15 -> -73000 | I15: =H15 -> -73000
B16: 1 | C16: =Inputs!C7*Inputs!C8*Inputs!C10 -> 131040 | D16: =Inputs!C17 -> 14400 | E16: =Inputs!C18 -> 5500 | F16: =C16-D16-E16 -> 111140 | G16: =1/(1+Inputs!C24)^B16 -> 0.92592593 | H16: =F16*G16 -> 102907.41 | I16: =I15+H16 -> 29907.407
B17: 2 | C17: =C16*(1+Inputs!C21) -> 134971.2 | D17: =D16*(1+Inputs!C22) -> 14976 | E17: =E16*(1+Inputs!C22) -> 5720 | F17: =C17-D17-E17 -> 114275.2 | G17: =1/(1+Inputs!C24)^B17 -> 0.85733882 | H17: =F17*G17 -> 97972.565 | I17: =I16+H17 -> 127879.97
B18: 3 | C18: =C17*(1+Inputs!C21) -> 139020.34 | D18: =D17*(1+Inputs!C22) -> 15575.04 | E18: =E17*(1+Inputs!C22) -> 5948.8 | F18: =C18-D18-E18 -> 117496.5 | G18: =1/(1+Inputs!C24)^B18 -> 0.79383224 | H18: =F18*G18 -> 93272.507 | I18: =I17+H18 -> 221152.48
B19: 4 | C19: =C18*(1+Inputs!C21) -> 143190.95 | D19: =D18*(1+Inputs!C22) -> 16198.042 | E19: =E18*(1+Inputs!C22) -> 6186.752 | F19: =C19-D19-E19 -> 120806.15 | G19: =1/(1+Inputs!C24)^B19 -> 0.73502985 | H19: =F19*G19 -> 88796.128 | I19: =I18+H19 -> 309948.61
B20: 5 | C20: =C19*(1+Inputs!C21) -> 147486.67 | D20: =D19*(1+Inputs!C22) -> 16845.963 | E20: =E19*(1+Inputs!C22) -> 6434.2221 | F20: =C20-D20-E20 -> 124206.49 | G20: =1/(1+Inputs!C24)^B20 -> 0.6805832 | H20: =F20*G20 -> 84532.849 | I20: =I19+H20 -> 394481.46
A21: TOTALS | C21: =SUM(C15:C20) -> 695709.16 | D21: =SUM(D15:D20) -> 77995.045 | E21: =SUM(E15:E20) -> 29789.774 | F21: =SUM(F15:F20) -> 514924.34 | G21: =SUM(G15:G20) -> 4.99271 | H21: =SUM(H15:H20) -> 394481.46 | I21: =SUM(I15:I20) -> 1010369.9
A23: Arizona State University
A24: University | B24: Year | C24: Labor Savings ($) | D24: Subscription ($) | E24: Maintenance ($) | F24: Net Cash Flow ($) | G24: Discount Factor | H24: PV of Cash Flow ($) | I24: Cumulative PV ($)
A25: Arizona State University | B25: 0 | C25: 0 | D25: 0 | E25: 0 | F25: =-(Inputs!D13+Inputs!D14) -> -135000 | G25: 1 | H25: =F25*G25 -> -135000 | I25: =H25 -> -135000
B26: 1 | C26: =Inputs!D7*Inputs!D8*Inputs!D10 -> 380362.5 | D26: =Inputs!D17 -> 32400 | E26: =Inputs!D18 -> 9000 | F26: =C26-D26-E26 -> 338962.5 | G26: =1/(1+Inputs!D24)^B26 -> 0.92592593 | H26: =F26*G26 -> 313854.17 | I26: =I25+H26 -> 178854.17
B27: 2 | C27: =C26*(1+Inputs!D21) -> 391773.38 | D27: =D26*(1+Inputs!D22) -> 33696 | E27: =E26*(1+Inputs!D22) -> 9360 | F27: =C27-D27-E27 -> 348717.38 | G27: =1/(1+Inputs!D24)^B27 -> 0.85733882 | H27: =F27*G27 -> 298968.94 | I27: =I26+H27 -> 477823.11
B28: 3 | C28: =C27*(1+Inputs!D21) -> 403526.58 | D28: =D27*(1+Inputs!D22) -> 35043.84 | E28: =E27*(1+Inputs!D22) -> 9734.4 | F28: =C28-D28-E28 -> 358748.34 | G28: =1/(1+Inputs!D24)^B28 -> 0.79383224 | H28: =F28*G28 -> 284786 | I28: =I27+H28 -> 762609.11
B29: 4 | C29: =C28*(1+Inputs!D21) -> 415632.37 | D29: =D28*(1+Inputs!D22) -> 36445.594 | E29: =E28*(1+Inputs!D22) -> 10123.776 | F29: =C29-D29-E29 -> 369063 | G29: =1/(1+Inputs!D24)^B29 -> 0.73502985 | H29: =F29*G29 -> 271272.33 | I29: =I28+H29 -> 1033881.4
B30: 5 | C30: =C29*(1+Inputs!D21) -> 428101.34 | D30: =D29*(1+Inputs!D22) -> 37903.417 | E30: =E29*(1+Inputs!D22) -> 10528.727 | F30: =C30-D30-E30 -> 379669.2 | G30: =1/(1+Inputs!D24)^B30 -> 0.6805832 | H30: =F30*G30 -> 258396.48 | I30: =I29+H30 -> 1292277.9
A31: TOTALS | C31: =SUM(C25:C30) -> 2019396.2 | D31: =SUM(D25:D30) -> 175488.85 | E31: =SUM(E25:E30) -> 48746.903 | F31: =SUM(F25:F30) -> 1660160.4 | G31: =SUM(G25:G30) -> 4.99271 | H31: =SUM(H25:H30) -> 1292277.9 | I31: =SUM(I25:I30) -> 3610445.7
A33: Input given : SJSU UNIVERSITY
A34: University | B34: Year | C34: Labor Savings ($) | D34: Subscription ($) | E34: Maintenance ($) | F34: Net Cash Flow ($) | G34: Discount Factor | H34: PV of Cash Flow ($) | I34: Cumulative PV ($)
A35: SJSU UNIVERSITY | B35: 0 | C35: 0 | D35: 0 | E35: 0 | F35: =-(Inputs!F13+Inputs!F14) -> -73000 | G35: 1 | H35: =F35*G35 -> -73000 | I35: =H35 -> -73000
B36: 1 | C36: =Inputs!F7*Inputs!F8*Inputs!F10 -> 174720 | D36: =Inputs!F17 -> 12000 | E36: =Inputs!F18 -> 5500 | F36: =C36-D36-E36 -> 157220 | G36: =1/(1+Inputs!F24)^B36 -> 0.92592593 | H36: =F36*G36 -> 145574.07 | I36: =I35+H36 -> 72574.074
B37: 2 | C37: =C36*(1+Inputs!F21) -> 179961.6 | D37: =D36*(1+Inputs!F22) -> 12480 | E37: =E36*(1+Inputs!F22) -> 5720 | F37: =C37-D37-E37 -> 161761.6 | G37: =1/(1+Inputs!F24)^B37 -> 0.85733882 | H37: =F37*G37 -> 138684.5 | I37: =I36+H37 -> 211258.57
B38: 3 | C38: =C37*(1+Inputs!F21) -> 185360.45 | D38: =D37*(1+Inputs!F22) -> 12979.2 | E38: =E37*(1+Inputs!F22) -> 5948.8 | F38: =C38-D38-E38 -> 166432.45 | G38: =1/(1+Inputs!F24)^B38 -> 0.79383224 | H38: =F38*G38 -> 132119.44 | I38: =I37+H38 -> 343378.02
B39: 4 | C39: =C38*(1+Inputs!F21) -> 190921.26 | D39: =D38*(1+Inputs!F22) -> 13498.368 | E39: =E38*(1+Inputs!F22) -> 6186.752 | F39: =C39-D39-E39 -> 171236.14 | G39: =1/(1+Inputs!F24)^B39 -> 0.73502985 | H39: =F39*G39 -> 125863.68 | I39: =I38+H39 -> 469241.69
B40: 5 | C40: =C39*(1+Inputs!F21) -> 196648.9 | D40: =D39*(1+Inputs!F22) -> 14038.303 | E40: =E39*(1+Inputs!F22) -> 6434.2221 | F40: =C40-D40-E40 -> 176176.37 | G40: =1/(1+Inputs!F24)^B40 -> 0.6805832 | H40: =F40*G40 -> 119902.68 | I40: =I39+H40 -> 589144.37
A41: TOTALS | C41: =SUM(C35:C40) -> 927612.21 | D41: =SUM(D35:D40) -> 64995.871 | E41: =SUM(E35:E40) -> 29789.774 | F41: =SUM(F35:F40) -> 759826.56 | G41: =SUM(G35:G40) -> 4.99271 | H41: =SUM(H35:H40) -> 589144.37 | I41: =SUM(I35:I40) -> 1612596.7

Sheet Economic Metrics
A1: ECONOMIC METRICS = NPV, IRR, Payback, BCR, Decision
A3: Metric | B3: UC Berkeley | C3: Stanford Univ. | D3: Arizona State Univ. | E3: SJSU UNIVERSITY
A4: Net Present Value (NPV) | B4: {=NPV(Inputs!B24,'Cash Flows'!F6:F10)+'Cash Flows'!F5} -> 756114.57 | C4: {=NPV(Inputs!C24,'Cash Flows'!F16:F20)+'Cash Flows'!F15} -> 394481.46 | D4: {=NPV(Inputs!D24,'Cash Flows'!F26:F30)+'Cash Flows'!F25} -> 1292277.9 | E4: {=NPV(Inputs!F24,'Cash Flows'!F36:F40)+'Cash Flows'!F35} -> 589144.37
A5: Internal Rate of Return (IRR) | B5: =IRR('Cash Flows'!F5:F10) -> 2.1485817 | C5: =IRR('Cash Flows'!F15:F20) -> 1.5339164 | D5: =IRR('Cash Flows'!F25:F30) -> 2.5343608 | E5: =IFERROR(IRR('Cash Flows'!F35:F40),"N/A") -> 2.1748828
A6: MARR (hurdle rate) | B6: =Inputs!B24 -> 0.08 | C6: =Inputs!C24 -> 0.08 | D6: =Inputs!D24 -> 0.08 | E6: =Inputs!F24 -> 0.08
A7: IRR − MARR Spread | B7: =IRR('Cash Flows'!F5:F10)-Inputs!B24 -> 2.0685817 | C7: =IRR('Cash Flows'!F15:F20)-Inputs!C24 -> 1.4539164 | D7: =IRR('Cash Flows'!F25:F30)-Inputs!D24 -> 2.4543608 | E7: =IFERROR(IRR('Cash Flows'!F35:F40)-Inputs!F24,"N/A") -> 2.0948828
A8: Total Undiscounted Benefits ($) | B8: =SUM('Cash Flows'!C6:C10) -> 1205895.9 | C8: =SUM('Cash Flows'!C16:C20) -> 695709.16 | D8: =SUM('Cash Flows'!C26:C30) -> 2019396.2 | E8: =SUM('Cash Flows'!C36:C40) -> 927612.21
A9: Total Recurring Costs ($) | B9: =SUM('Cash Flows'!D6:D10)+SUM('Cash Flows'!E6:E10) -> 135408.06 | C9: =SUM('Cash Flows'!D16:D20)+SUM('Cash Flows'!E16:E20) -> 107784.82 | D9: =SUM('Cash Flows'!D26:D30)+SUM('Cash Flows'!E26:E30) -> 224235.75 | E9: =SUM('Cash Flows'!D36:D40)+SUM('Cash Flows'!E36:E40) -> 94785.645
A10: Year 0 Investment ($) | B10: =-'Cash Flows'!F5 -> 95000 | C10: =-'Cash Flows'!F15 -> 73000 | D10: =-'Cash Flows'!F25 -> 135000 | E10: =-'Cash Flows'!F35 -> 73000
A11: Benefit-Cost Ratio (BCR) | B11: =SUM('Cash Flows'!C6:C10)/(-'Cash Flows'!F5+SUM('Cash Flows'!D6:D10)+SUM('Cash Flows'!E6:E10)) -> 5.2337399 | C11: =SUM('Cash Flows'!C16:C20)/(-'Cash Flows'!F15+SUM('Cash Flows'!D16:D20)+SUM('Cash Flows'!E16:E20)) -> 3.848272 | D11: =SUM('Cash Flows'!C26:C30)/(-'Cash Flows'!F25+SUM('Cash Flows'!D26:D30)+SUM('Cash Flows'!E26:E30)) -> 5.6213674 | E11: =IFERROR(SUM('Cash Flows'!C36:C40)/(-'Cash Flows'!F35+SUM('Cash Flows'!D36:D40)+SUM('Cash Flows'!E36:E40)),"N/A") -> 5.5285553
A12: DECISION | B12: {=IF(NPV(Inputs!B24,'Cash Flows'!F6:F10)+'Cash Flows'!F5>0,"ACCEPT","REJECT")} -> ACCEPT | C12: {=IF(NPV(Inputs!C24,'Cash Flows'!F16:F20)+'Cash Flows'!F15>0,"ACCEPT","REJECT")} -> ACCEPT | D12: {=IF(NPV(Inputs!D24,'Cash Flows'!F26:F30)+'Cash Flows'!F25>0,"ACCEPT","REJECT")} -> ACCEPT | E12: {=IF(NPV(Inputs!F24,'Cash Flows'!F36:F40)+'Cash Flows'!F35>0,"ACCEPT","REJECT")} -> ACCEPT
A14: DISCOUNTED PAYBACK PERIOD (Year when Cumulative PV turns positive)
A15: Year | B15: Cumul. PV UC Berkeley | C15: Cumul. PV Stanford University | D15: Cumul. PV Arizona State University | E15: Cumul. PV Your University | F15: Status
A16: 0 | B16: ='Cash Flows'!I5 -> -95000 | C16: ='Cash Flows'!I15 -> -73000 | D16: ='Cash Flows'!I25 -> -135000 | E16: ='Cash Flows'!I35 -> -73000 | F16: =IF(AND(B16>=0,C16>=0,D16>=0),"All recovered","Payback pending") -> Payback pending
A17: 1 | B17: ='Cash Flows'!I6 -> 92162.963 | C17: ='Cash Flows'!I16 -> 29907.407 | D17: ='Cash Flows'!I26 -> 178854.17 | E17: ='Cash Flows'!I36 -> 72574.074 | F17: =IF(AND(B17>=0,C17>=0,D17>=0),"All recovered","Payback pending") -> All recovered
A18: 2 | B18: ='Cash Flows'!I7 -> 270446.64 | C18: ='Cash Flows'!I17 -> 127879.97 | D18: ='Cash Flows'!I27 -> 477823.11 | E18: ='Cash Flows'!I37 -> 211258.57 | F18: =IF(AND(B18>=0,C18>=0,D18>=0),"All recovered","Payback pending") -> All recovered
A19: 3 | B19: ='Cash Flows'!I8 -> 440270.05 | C19: ='Cash Flows'!I18 -> 221152.48 | D19: ='Cash Flows'!I28 -> 762609.11 | E19: ='Cash Flows'!I38 -> 343378.02 | F19: =IF(AND(B19>=0,C19>=0,D19>=0),"All recovered","Payback pending") -> All recovered
A20: 4 | B20: ='Cash Flows'!I9 -> 602032.5 | C20: ='Cash Flows'!I19 -> 309948.61 | D20: ='Cash Flows'!I29 -> 1033881.4 | E20: ='Cash Flows'!I39 -> 469241.69 | F20: =IF(AND(B20>=0,C20>=0,D20>=0),"All recovered","Payback pending") -> All recovered
A21: 5 | B21: ='Cash Flows'!I10 -> 756114.57 | C21: ='Cash Flows'!I20 -> 394481.46 | D21: ='Cash Flows'!I30 -> 1292277.9 | E21: ='Cash Flows'!I40 -> 589144.37 | F21: =IF(AND(B21>=0,C21>=0,D21>=0),"All recovered","Payback pending") -> All recovered

Sheet Sensitivity
A1: SENSITIVITY ANALYSIS
A3: SECTION 1 — WORKFORCE REDUCTION SENSITIVITY (base = 35%, range = 25% to 45%)
A5: Scenario | B5: Reduction % | C5: ← UCB → | J5: ← Stanford → | Q5: ← ASU → | X5: ← SJSU → | AE5: ← NPV Results → | AI5: Best NPV
A6: Scenario | B6: % | C6: UCB Yr1 Sav | D6: UCB Yr1 Cost | E6: UCB Yr1 CF | F6: UCB Yr2 CF | G6: UCB Yr3 CF | H6: UCB Yr4 CF | I6: UCB Yr5 CF | J6: SU Yr1 Sav | K6: SU Yr1 Cost | L6: SU Yr1 CF | M6: SU Yr2 CF | N6: SU Yr3 CF | O6: SU Yr4 CF | P6: SU Yr5 CF | Q6: ASU Yr1 Sav | R6: ASU Yr1 Cost | S6: ASU Yr1 CF | T6: ASU Yr2 CF | U6: ASU Yr3 CF | V6: ASU Yr4 CF | W6: ASU Yr5 CF | X6: SJSU Yr1 Sav | Y6: SJSU Yr1 Cost | Z6: SJSU Yr1 CF | AA6: SJSU Yr2 CF | AB6: SJSU Yr3 CF | AC6: SJSU Yr4 CF | AD6: SJSU Yr5 CF | AE6: NPV UCB | AF6: NPV Stanford | AG6: NPV ASU | AH6: NPV SJSU | AI6: Best NPV
A7: 25% (Pessimistic) | B7: 0.25 | C7: =Inputs!B7*Inputs!B8*0.25 -> 162240 | D7: =Inputs!B17+Inputs!B18 -> 25000 | E7: =C7*(1+Inputs!B21)^0-D7*(1+Inputs!B22)^0 -> 137240 | F7: =C7*(1+Inputs!B21)^1-D7*(1+Inputs!B22)^1 -> 141107.2 | G7: =C7*(1+Inputs!B21)^2-D7*(1+Inputs!B22)^2 -> 145080.42 | H7: =C7*(1+Inputs!B21)^3-D7*(1+Inputs!B22)^3 -> 149162.43 | I7: =C7*(1+Inputs!B21)^4-D7*(1+Inputs!B22)^4 -> 153356.09 | J7: =Inputs!C7*Inputs!C8*0.25 -> 93600 | K7: =Inputs!C17+Inputs!C18 -> 19900 | L7: =J7*(1+Inputs!C21)^0-K7*(1+Inputs!C22)^0 -> 73700 | M7: =J7*(1+Inputs!C21)^1-K7*(1+Inputs!C22)^1 -> 75712 | N7: =J7*(1+Inputs!C21)^2-K7*(1+Inputs!C22)^2 -> 77776.4 | O7: =J7*(1+Inputs!C21)^3-K7*(1+Inputs!C22)^3 -> 79894.454 | P7: =J7*(1+Inputs!C21)^4-K7*(1+Inputs!C22)^4 -> 82067.439 | Q7: =Inputs!D7*Inputs!D8*0.25 -> 271687.5 | R7: =Inputs!D17+Inputs!D18 -> 41400 | S7: =Q7*(1+Inputs!D21)^0-R7*(1+Inputs!D22)^0 -> 230287.5 | T7: =Q7*(1+Inputs!D21)^1-R7*(1+Inputs!D22)^1 -> 236782.12 | U7: =Q7*(1+Inputs!D21)^2-R7*(1+Inputs!D22)^2 -> 243455.03 | V7: =Q7*(1+Inputs!D21)^3-R7*(1+Inputs!D22)^3 -> 250310.9 | W7: =Q7*(1+Inputs!D21)^4-R7*(1+Inputs!D22)^4 -> 257354.53 | X7: =Inputs!F7*Inputs!F8*0.25 -> 124800 | Y7: =Inputs!F17+Inputs!F18 -> 17500 | Z7: =X7*(1+Inputs!F21)^0-Y7*(1+Inputs!F22)^0 -> 107300 | AA7: =X7*(1+Inputs!F21)^1-Y7*(1+Inputs!F22)^1 -> 110344 | AB7: =X7*(1+Inputs!F21)^2-Y7*(1+Inputs!F22)^2 -> 113472.32 | AC7: =X7*(1+Inputs!F21)^3-Y7*(1+Inputs!F22)^3 -> 116687.21 | AD7: =X7*(1+Inputs!F21)^4-Y7*(1+Inputs!F22)^4 -> 119990.97 | AE7: {=NPV(Inputs!B24,E7,F7,G7,H7,I7)-(Inputs!B13+Inputs!B14)} -> 482230.68 | AF7: {=NPV(Inputs!C24,L7,M7,N7,O7,P7)-(Inputs!C13+Inputs!C14)} -> 236471.52 | AG7: {=NPV(Inputs!D24,S7,T7,U7,V7,W7)-(Inputs!D13+Inputs!D14)} -> 833631.28 | AH7: {=NPV(Inputs!F24,Z7,AA7,AB7,AC7,AD7)-(Inputs!F13+Inputs!F14)} -> 378464.46 | AI7: =MAX(AE7,AF7,AG7,AH7) -> 833631.28
A8: 35% (Base Case) | B8: 0.35 | C8: =Inputs!B7*Inputs!B8*0.35 -> 227136 | D8: =Inputs!B17+Inputs!B18 -> 25000 | E8: =C8*(1+Inputs!B21)^0-D8*(1+Inputs!B22)^0 -> 202136 | F8: =C8*(1+Inputs!B21)^1-D8*(1+Inputs!B22)^1 -> 207950.08 | G8: =C8*(1+Inputs!B21)^2-D8*(1+Inputs!B22)^2 -> 213928.58 | H8: =C8*(1+Inputs!B21)^3-D8*(1+Inputs!B22)^3 -> 220076.04 | I8: =C8*(1+Inputs!B21)^4-D8*(1+Inputs!B22)^4 -> 226397.11 | J8: =Inputs!C7*Inputs!C8*0.35 -> 131040 | K8: =Inputs!C17+Inputs!C18 -> 19900 | L8: =J8*(1+Inputs!C21)^0-K8*(1+Inputs!C22)^0 -> 111140 | M8: =J8*(1+Inputs!C21)^1-K8*(1+Inputs!C22)^1 -> 114275.2 | N8: =J8*(1+Inputs!C21)^2-K8*(1+Inputs!C22)^2 -> 117496.5 | O8: =J8*(1+Inputs!C21)^3-K8*(1+Inputs!C22)^3 -> 120806.15 | P8: =J8*(1+Inputs!C21)^4-K8*(1+Inputs!C22)^4 -> 124206.49 | Q8: =Inputs!D7*Inputs!D8*0.35 -> 380362.5 | R8: =Inputs!D17+Inputs!D18 -> 41400 | S8: =Q8*(1+Inputs!D21)^0-R8*(1+Inputs!D22)^0 -> 338962.5 | T8: =Q8*(1+Inputs!D21)^1-R8*(1+Inputs!D22)^1 -> 348717.38 | U8: =Q8*(1+Inputs!D21)^2-R8*(1+Inputs!D22)^2 -> 358748.34 | V8: =Q8*(1+Inputs!D21)^3-R8*(1+Inputs!D22)^3 -> 369063 | W8: =Q8*(1+Inputs!D21)^4-R8*(1+Inputs!D22)^4 -> 379669.2 | X8: =Inputs!F7*Inputs!F8*0.35 -> 174720 | Y8: =Inputs!F17+Inputs!F18 -> 17500 | Z8: =X8*(1+Inputs!F21)^0-Y8*(1+Inputs!F22)^0 -> 157220 | AA8: =X8*(1+Inputs!F21)^1-Y8*(1+Inputs!F22)^1 -> 161761.6 | AB8: =X8*(1+Inputs!F21)^2-Y8*(1+Inputs!F22)^2 -> 166432.45 | AC8: =X8*(1+Inputs!F21)^3-Y8*(1+Inputs!F22)^3 -> 171236.14 | AD8: =X8*(1+Inputs!F21)^4-Y8*(1+Inputs!F22)^4 -> 176176.37 | AE8: {=NPV(Inputs!B24,E8,F8,G8,H8,I8)-(Inputs!B13+Inputs!B14)} -> 756114.57 | AF8: {=NPV(Inputs!C24,L8,M8,N8,O8,P8)-(Inputs!C13+Inputs!C14)} -> 394481.46 | AG8: {=NPV(Inputs!D24,S8,T8,U8,V8,W8)-(Inputs!D13+Inputs!D14)} -> 1292277.9 | AH8: {=NPV(Inputs!F24,Z8,AA8,AB8,AC8,AD8)-(Inputs!F13+Inputs!F14)} -> 589144.37 | AI8: =MAX(AE8,AF8,AG8,AH8) -> 1292277.9
A9: 45% (Optimistic) | B9: 0.45 | C9: =Inputs!B7*Inputs!B8*0.45 -> 292032 | D9: =Inputs!B17+Inputs!B18 -> 25000 | E9: =C9*(1+Inputs!B21)^0-D9*(1+Inputs!B22)^0 -> 267032 | F9: =C9*(1+Inputs!B21)^1-D9*(1+Inputs!B22)^1 -> 274792.96 | G9: =C9*(1+Inputs!B21)^2-D9*(1+Inputs!B22)^2 -> 282776.75 | H9: =C9*(1+Inputs!B21)^3-D9*(1+Inputs!B22)^3 -> 290989.65 | I9: =C9*(1+Inputs!B21)^4-D9*(1+Inputs!B22)^4 -> 299438.12 | J9: =Inputs!C7*Inputs!C8*0.45 -> 168480 | K9: =Inputs!C17+Inputs!C18 -> 19900 | L9: =J9*(1+Inputs!C21)^0-K9*(1+Inputs!C22)^0 -> 148580 | M9: =J9*(1+Inputs!C21)^1-K9*(1+Inputs!C22)^1 -> 152838.4 | N9: =J9*(1+Inputs!C21)^2-K9*(1+Inputs!C22)^2 -> 157216.59 | O9: =J9*(1+Inputs!C21)^3-K9*(1+Inputs!C22)^3 -> 161717.85 | P9: =J9*(1+Inputs!C21)^4-K9*(1+Inputs!C22)^4 -> 166345.54 | Q9: =Inputs!D7*Inputs!D8*0.45 -> 489037.5 | R9: =Inputs!D17+Inputs!D18 -> 41400 | S9: =Q9*(1+Inputs!D21)^0-R9*(1+Inputs!D22)^0 -> 447637.5 | T9: =Q9*(1+Inputs!D21)^1-R9*(1+Inputs!D22)^1 -> 460652.62 | U9: =Q9*(1+Inputs!D21)^2-R9*(1+Inputs!D22)^2 -> 474041.64 | V9: =Q9*(1+Inputs!D21)^3-R9*(1+Inputs!D22)^3 -> 487815.11 | W9: =Q9*(1+Inputs!D21)^4-R9*(1+Inputs!D22)^4 -> 501983.87 | X9: =Inputs!F7*Inputs!F8*0.45 -> 224640 | Y9: =Inputs!F17+Inputs!F18 -> 17500 | Z9: =X9*(1+Inputs!F21)^0-Y9*(1+Inputs!F22)^0 -> 207140 | AA9: =X9*(1+Inputs!F21)^1-Y9*(1+Inputs!F22)^1 -> 213179.2 | AB9: =X9*(1+Inputs!F21)^2-Y9*(1+Inputs!F22)^2 -> 219392.58 | AC9: =X9*(1+Inputs!F21)^3-Y9*(1+Inputs!F22)^3 -> 225785.07 | AD9: =X9*(1+Inputs!F21)^4-Y9*(1+Inputs!F22)^4 -> 232361.77 | AE9: {=NPV(Inputs!B24,E9,F9,G9,H9,I9)-(Inputs!B13+Inputs!B14)} -> 1029998.5 | AF9: {=NPV(Inputs!C24,L9,M9,N9,O9,P9)-(Inputs!C13+Inputs!C14)} -> 552491.39 | AG9: {=NPV(Inputs!D24,S9,T9,U9,V9,W9)-(Inputs!D13+Inputs!D14)} -> 1750924.5 | AH9: {=NPV(Inputs!F24,Z9,AA9,AB9,AC9,AD9)-(Inputs!F13+Inputs!F14)} -> 799824.29 | AI9: =MAX(AE9,AF9,AG9,AH9) -> 1750924.5
A11: SECTION 2 — MARR / DISCOUNT RATE SENSITIVITY (base = 8%)
A13: Scenario | B13: MARR % | C13: UCB Yr0 | D13: UCB Yr1 CF | E13: UCB Yr2 CF | F13: UCB Yr3 CF | G13: UCB Yr4 CF | H13: UCB Yr5 CF | I13: SU Yr0 | J13: SU Yr1 CF | K13: SU Yr2 CF | L13: SU Yr3 CF | M13: SU Yr4 CF | N13: SU Yr5 CF | O13: ASU Yr0 | P13: ASU Yr1 CF | Q13: ASU Yr2 CF | R13: ASU Yr3 CF | S13: ASU Yr4 CF | T13: ASU Yr5 CF | U13: SJSU Yr0 | V13: SJSU Yr1 CF | W13: SJSU Yr2 CF | X13: SJSU Yr3 CF | Y13: SJSU Yr4 CF | Z13: SJSU Yr5 CF | AE13: NPV UCB | AF13: NPV Stanford | AG13: NPV ASU | AH13: NPV SJSU | AI13: Best NPV
A14: 6% (Low) | B14: 0.06 | C14: ='Cash Flows'!F5 -> -95000 | D14: ='Cash Flows'!F6 -> 202136 | E14: ='Cash Flows'!F7 -> 207950.08 | F14: ='Cash Flows'!F8 -> 213928.58 | G14: ='Cash Flows'!F9 -> 220076.04 | H14: ='Cash Flows'!F10 -> 226397.11 | I14: ='Cash Flows'!F15 -> -73000 | J14: ='Cash Flows'!F16 -> 111140 | K14: ='Cash Flows'!F17 -> 114275.2 | L14: ='Cash Flows'!F18 -> 117496.5 | M14: ='Cash Flows'!F19 -> 120806.15 | N14: ='Cash Flows'!F20 -> 124206.49 | O14: ='Cash Flows'!F25 -> -135000 | P14: ='Cash Flows'!F26 -> 338962.5 | Q14: ='Cash Flows'!F27 -> 348717.38 | R14: ='Cash Flows'!F28 -> 358748.34 | S14: ='Cash Flows'!F29 -> 369063 | T14: ='Cash Flows'!F30 -> 379669.2 | U14: ='Cash Flows'!F35 -> -73000 | V14: ='Cash Flows'!F36 -> 157220 | W14: ='Cash Flows'!F37 -> 161761.6 | X14: ='Cash Flows'!F38 -> 166432.45 | Y14: ='Cash Flows'!F39 -> 171236.14 | Z14: ='Cash Flows'!F40 -> 176176.37 | AE14: {=NPV(0.06,D14,E14,F14,G14,H14)+C14} -> 803885.66 | AF14: {=NPV(0.06,J14,K14,L14,M14,N14)+I14} -> 420710 | AG14: {=NPV(0.06,P14,Q14,R14,S14,T14)+O14} -> 1372388.6 | AH14: {=NPV(0.06,V14,W14,X14,Y14,Z14)+U14} -> 626312.19 | AI14: =MAX(AE14,AF14,AG14,AH14) -> 1372388.6
A15: 8% (Base Case) | B15: 0.08 | C15: ='Cash Flows'!F5 -> -95000 | D15: ='Cash Flows'!F6 -> 202136 | E15: ='Cash Flows'!F7 -> 207950.08 | F15: ='Cash Flows'!F8 -> 213928.58 | G15: ='Cash Flows'!F9 -> 220076.04 | H15: ='Cash Flows'!F10 -> 226397.11 | I15: ='Cash Flows'!F15 -> -73000 | J15: ='Cash Flows'!F16 -> 111140 | K15: ='Cash Flows'!F17 -> 114275.2 | L15: ='Cash Flows'!F18 -> 117496.5 | M15: ='Cash Flows'!F19 -> 120806.15 | N15: ='Cash Flows'!F20 -> 124206.49 | O15: ='Cash Flows'!F25 -> -135000 | P15: ='Cash Flows'!F26 -> 338962.5 | Q15: ='Cash Flows'!F27 -> 348717.38 | R15: ='Cash Flows'!F28 -> 358748.34 | S15: ='Cash Flows'!F29 -> 369063 | T15: ='Cash Flows'!F30 -> 379669.2 | U15: ='Cash Flows'!F35 -> -73000 | V15: ='Cash Flows'!F36 -> 157220 | W15: ='Cash Flows'!F37 -> 161761.6 | X15: ='Cash Flows'!F38 -> 166432.45 | Y15: ='Cash Flows'!F39 -> 171236.14 | Z15: ='Cash Flows'!F40 -> 176176.37 | AE15: {=NPV(0.08,D15,E15,F15,G15,H15)+C15} -> 756114.57 | AF15: {=NPV(0.08,J15,K15,L15,M15,N15)+I15} -> 394481.46 | AG15: {=NPV(0.08,P15,Q15,R15,S15,T15)+O15} -> 1292277.9 | AH15: {=NPV(0.08,V15,W15,X15,Y15,Z15)+U15} -> 589144.37 | AI15: =MAX(AE15,AF15,AG15,AH15) -> 1292277.9
A16: 10% (High) | B16: 0.1 | C16: ='Cash Flows'!F5 -> -95000 | D16: ='Cash Flows'!F6 -> 202136 | E16: ='Cash Flows'!F7 -> 207950.08 | F16: ='Cash Flows'!F8 -> 213928.58 | G16: ='Cash Flows'!F9 -> 220076.04 | H16: ='Cash Flows'!F10 -> 226397.11 | I16: ='Cash Flows'!F15 -> -73000 | J16: ='Cash Flows'!F16 -> 111140 | K16: ='Cash Flows'!F17 -> 114275.2 | L16: ='Cash Flows'!F18 -> 117496.5 | M16: ='Cash Flows'!F19 -> 120806.15 | N16: ='Cash Flows'!F20 -> 124206.49 | O16: ='Cash Flows'!F25 -> -135000 | P16: ='Cash Flows'!F26 -> 338962.5 | Q16: ='Cash Flows'!F27 -> 348717.38 | R16: ='Cash Flows'!F28 -> 358748.34 | S16: ='Cash Flows'!F29 -> 369063 | T16: ='Cash Flows'!F30 -> 379669.2 | U16: ='Cash Flows'!F35 -> -73000 | V16: ='Cash Flows'!F36 -> 157220 | W16: ='Cash Flows'!F37 -> 161761.6 | X16: ='Cash Flows'!F38 -> 166432.45 | Y16: ='Cash Flows'!F39 -> 171236.14 | Z16: ='Cash Flows'!F40 -> 176176.37 | AE16: {=NPV(0.1,D16,E16,F16,G16,H16)+C16} -> 712236.97 | AF16: {=NPV(0.1,J16,K16,L16,M16,N16)+I16} -> 370390.22 | AG16: {=NPV(0.1,P16,Q16,R16,S16,T16)+O16} -> 1218696.5 | AH16: {=NPV(0.1,V16,W16,X16,Y16,Z16)+U16} -> 555005.96 | AI16: =MAX(AE16,AF16,AG16,AH16) -> 1218696.5
A17: 12% (Conservative) | B17: 0.12 | C17: ='Cash Flows'!F5 -> -95000 | D17: ='Cash Flows'!F6 -> 202136 | E17: ='Cash Flows'!F7 -> 207950.08 | F17: ='Cash Flows'!F8 -> 213928.58 | G17: ='Cash Flows'!F9 -> 220076.04 | H17: ='Cash Flows'!F10 -> 226397.11 | I17: ='Cash Flows'!F15 -> -73000 | J17: ='Cash Flows'!F16 -> 111140 | K17: ='Cash Flows'!F17 -> 114275.2 | L17: ='Cash Flows'!F18 -> 117496.5 | M17: ='Cash Flows'!F19 -> 120806.15 | N17: ='Cash Flows'!F20 -> 124206.49 | O17: ='Cash Flows'!F25 -> -135000 | P17: ='Cash Flows'!F26 -> 338962.5 | Q17: ='Cash Flows'!F27 -> 348717.38 | R17: ='Cash Flows'!F28 -> 358748.34 | S17: ='Cash Flows'!F29 -> 369063 | T17: ='Cash Flows'!F30 -> 379669.2 | U17: ='Cash Flows'!F35 -> -73000 | V17: ='Cash Flows'!F36 -> 157220 | W17: ='Cash Flows'!F37 -> 161761.6 | X17: ='Cash Flows'!F38 -> 166432.45 | Y17: ='Cash Flows'!F39 -> 171236.14 | Z17: ='Cash Flows'!F40 -> 176176.37 | AE17: {=NPV(0.12,D17,E17,F17,G17,H17)+C17} -> 671851.34 | AF17: {=NPV(0.12,J17,K17,L17,M17,N17)+I17} -> 348215.91 | AG17: {=NPV(0.12,P17,Q17,R17,S17,T17)+O17} -> 1150971.1 | AH17: {=NPV(0.12,V17,W17,X17,Y17,Z17)+U17} -> 523584.56 | AI17: =MAX(AE17,AF17,AG17,AH17) -> 1150971.1
A19: SECTION 3 — SETUP COST SENSITIVITY (base = ×1.0)
A21: Scenario | B21: Multiplier | C21: UCB Setup Cost | D21: UCB Year 0 Total | E21: SU Setup Cost | F21: SU Year 0 Total | G21: ASU Setup Cost | H21: ASU Year 0 Total | I21: SJSU Setup Cost | J21: SJSU Year 0 Total | AE21: NPV UCB | AF21: NPV Stanford | AG21: NPV ASU | AH21: NPV SJSU | AI21: Best NPV
A22: Optimistic (−30%) | B22: 0.7 | C22: =Inputs!B13*0.7 -> 59500 | D22: =C22+Inputs!B14 -> 69500 | E22: =Inputs!C13*0.7 -> 45500 | F22: =E22+Inputs!C14 -> 53500 | G22: =Inputs!D13*0.7 -> 84000 | H22: =G22+Inputs!D14 -> 99000 | I22: =Inputs!F13*0.7 -> 45500 | J22: =I22+Inputs!F14 -> 53500 | AE22: {=NPV(Inputs!B24,'Cash Flows'!F6:F10)-D22} -> 781614.57 | AF22: {=NPV(Inputs!C24,'Cash Flows'!F16:F20)-F22} -> 413981.46 | AG22: {=NPV(Inputs!D24,'Cash Flows'!F26:F30)-H22} -> 1328277.9 | AH22: {=NPV(Inputs!F24,'Cash Flows'!F36:F40)-J22} -> 608644.37 | AI22: =MAX(AE22,AF22,AG22,AH22) -> 1328277.9
A23: Base Case (×1.0) | B23: 1 | C23: =Inputs!B13*1 -> 85000 | D23: =C23+Inputs!B14 -> 95000 | E23: =Inputs!C13*1 -> 65000 | F23: =E23+Inputs!C14 -> 73000 | G23: =Inputs!D13*1 -> 120000 | H23: =G23+Inputs!D14 -> 135000 | I23: =Inputs!F13*1 -> 65000 | J23: =I23+Inputs!F14 -> 73000 | AE23: {=NPV(Inputs!B24,'Cash Flows'!F6:F10)-D23} -> 756114.57 | AF23: {=NPV(Inputs!C24,'Cash Flows'!F16:F20)-F23} -> 394481.46 | AG23: {=NPV(Inputs!D24,'Cash Flows'!F26:F30)-H23} -> 1292277.9 | AH23: {=NPV(Inputs!F24,'Cash Flows'!F36:F40)-J23} -> 589144.37 | AI23: =MAX(AE23,AF23,AG23,AH23) -> 1292277.9
A24: Overrun (+50%) | B24: 1.5 | C24: =Inputs!B13*1.5 -> 127500 | D24: =C24+Inputs!B14 -> 137500 | E24: =Inputs!C13*1.5 -> 97500 | F24: =E24+Inputs!C14 -> 105500 | G24: =Inputs!D13*1.5 -> 180000 | H24: =G24+Inputs!D14 -> 195000 | I24: =Inputs!F13*1.5 -> 97500 | J24: =I24+Inputs!F14 -> 105500 | AE24: {=NPV(Inputs!B24,'Cash Flows'!F6:F10)-D24} -> 713614.57 | AF24: {=NPV(Inputs!C24,'Cash Flows'!F16:F20)-F24} -> 361981.46 | AG24: {=NPV(Inputs!D24,'Cash Flows'!F26:F30)-H24} -> 1232277.9 | AH24: {=NPV(Inputs!F24,'Cash Flows'!F36:F40)-J24} -> 556644.37 | AI24: =MAX(AE24,AF24,AG24,AH24) -> 1232277.9
A25: High Risk (×2.0) | B25: 2 | C25: =Inputs!B13*2 -> 170000 | D25: =C25+Inputs!B14 -> 180000 | E25: =Inputs!C13*2 -> 130000 | F25: =E25+Inputs!C14 -> 138000 | G25: =Inputs!D13*2 -> 240000 | H25: =G25+Inputs!D14 -> 255000 | I25: =Inputs!F13*2 -> 130000 | J25: =I25+Inputs!F14 -> 138000 | AE25: {=NPV(Inputs!B24,'Cash Flows'!F6:F10)-D25} -> 671114.57 | AF25: {=NPV(Inputs!C24,'Cash Flows'!F16:F20)-F25} -> 329481.46 | AG25: {=NPV(Inputs!D24,'Cash Flows'!F26:F30)-H25} -> 1172277.9 | AH25: {=NPV(Inputs!F24,'Cash Flows'!F36:F40)-J25} -> 524144.37 | AI25: =MAX(AE25,AF25,AG25,AH25) -> 1172277.9
A27: SECTION 4 — SUBSCRIPTION COST SENSITIVITY
A29: Scenario | B29: Annual Subscription | C29: UCB Yr1 Sav | D29: UCB Yr1 Cost | E29: UCB Yr1 CF | F29: UCB Yr2 CF | G29: UCB Yr3 CF | H29: UCB Yr4 CF | I29: UCB Yr5 CF | J29: SU Yr1 Sav | K29: SU Yr1 Cost | L29: SU Yr1 CF | M29: SU Yr2 CF | N29: SU Yr3 CF | O29: SU Yr4 CF | P29: SU Yr5 CF | Q29: ASU Yr1 Sav | R29: ASU Yr1 Cost | S29: ASU Yr1 CF | T29: ASU Yr2 CF | U29: ASU Yr3 CF | V29: ASU Yr4 CF | W29: ASU Yr5 CF | X29: SJSU Yr1 Sav | Y29: SJSU Yr1 Cost | Z29: SJSU Yr1 CF | AA29: SJSU Yr2 CF | AB29: SJSU Yr3 CF | AC29: SJSU Yr4 CF | AD29: SJSU Yr5 CF | AE29: NPV UCB | AF29: NPV Stanford | AG29: NPV ASU | AH29: NPV SJSU | AI29: Best NPV
A30: $5,000 / yr (Low tier) | B30: 5000 | C30: =Inputs!B7*Inputs!B8*Inputs!B10 -> 227136 | D30: =5000+Inputs!B18 -> 12000 | E30: =C30*(1+Inputs!B21)^0-D30*(1+Inputs!B22)^0 -> 215136 | F30: =C30*(1+Inputs!B21)^1-D30*(1+Inputs!B22)^1 -> 221470.08 | G30: =C30*(1+Inputs!B21)^2-D30*(1+Inputs!B22)^2 -> 227989.38 | H30: =C30*(1+Inputs!B21)^3-D30*(1+Inputs!B22)^3 -> 234699.27 | I30: =C30*(1+Inputs!B21)^4-D30*(1+Inputs!B22)^4 -> 241605.27 | J30: =Inputs!C7*Inputs!C8*Inputs!C10 -> 131040 | K30: =5000+Inputs!C18 -> 10500 | L30: =J30*(1+Inputs!C21)^0-K30*(1+Inputs!C22)^0 -> 120540 | M30: =J30*(1+Inputs!C21)^1-K30*(1+Inputs!C22)^1 -> 124051.2 | N30: =J30*(1+Inputs!C21)^2-K30*(1+Inputs!C22)^2 -> 127663.54 | O30: =J30*(1+Inputs!C21)^3-K30*(1+Inputs!C22)^3 -> 131379.87 | P30: =J30*(1+Inputs!C21)^4-K30*(1+Inputs!C22)^4 -> 135203.16 | Q30: =Inputs!D7*Inputs!D8*Inputs!D10 -> 380362.5 | R30: =5000+Inputs!D18 -> 14000 | S30: =Q30*(1+Inputs!D21)^0-R30*(1+Inputs!D22)^0 -> 366362.5 | T30: =Q30*(1+Inputs!D21)^1-R30*(1+Inputs!D22)^1 -> 377213.38 | U30: =Q30*(1+Inputs!D21)^2-R30*(1+Inputs!D22)^2 -> 388384.18 | V30: =Q30*(1+Inputs!D21)^3-R30*(1+Inputs!D22)^3 -> 399884.28 | W30: =Q30*(1+Inputs!D21)^4-R30*(1+Inputs!D22)^4 -> 411723.32 | X30: =Inputs!F7*Inputs!F8*Inputs!F10 -> 174720 | Y30: =5000+Inputs!F18 -> 10500 | Z30: =X30*(1+Inputs!F21)^0-Y30*(1+Inputs!F22)^0 -> 164220 | AA30: =X30*(1+Inputs!F21)^1-Y30*(1+Inputs!F22)^1 -> 169041.6 | AB30: =X30*(1+Inputs!F21)^2-Y30*(1+Inputs!F22)^2 -> 174003.65 | AC30: =X30*(1+Inputs!F21)^3-Y30*(1+Inputs!F22)^3 -> 179110.19 | AD30: =X30*(1+Inputs!F21)^4-Y30*(1+Inputs!F22)^4 -> 184365.38 | AE30: {=NPV(Inputs!B24,E30,F30,G30,H30,I30)-(Inputs!B13+Inputs!B14)} -> 812003.68 | AF30: {=NPV(Inputs!C24,L30,M30,N30,O30,P30)-(Inputs!C13+Inputs!C14)} -> 434893.58 | AG30: {=NPV(Inputs!D24,S30,T30,U30,V30,W30)-(Inputs!D13+Inputs!D14)} -> 1410074.9 | AH30: {=NPV(Inputs!F24,Z30,AA30,AB30,AC30,AD30)-(Inputs!F13+Inputs!F14)} -> 619238.51 | AI30: =MAX(AE30,AF30,AG30,AH30) -> 1410074.9
A31: Base Case (from Inputs) | B31: From Inputs | C31: =Inputs!B7*Inputs!B8*Inputs!B10 -> 227136 | D31: =Inputs!B17+Inputs!B18 -> 25000 | E31: =C31*(1+Inputs!B21)^0-D31*(1+Inputs!B22)^0 -> 202136 | F31: =C31*(1+Inputs!B21)^1-D31*(1+Inputs!B22)^1 -> 207950.08 | G31: =C31*(1+Inputs!B21)^2-D31*(1+Inputs!B22)^2 -> 213928.58 | H31: =C31*(1+Inputs!B21)^3-D31*(1+Inputs!B22)^3 -> 220076.04 | I31: =C31*(1+Inputs!B21)^4-D31*(1+Inputs!B22)^4 -> 226397.11 | J31: =Inputs!C7*Inputs!C8*Inputs!C10 -> 131040 | K31: =Inputs!C17+Inputs!C18 -> 19900 | L31: =J31*(1+Inputs!C21)^0-K31*(1+Inputs!C22)^0 -> 111140 | M31: =J31*(1+Inputs!C21)^1-K31*(1+Inputs!C22)^1 -> 114275.2 | N31: =J31*(1+Inputs!C21)^2-K31*(1+Inputs!C22)^2 -> 117496.5 | O31: =J31*(1+Inputs!C21)^3-K31*(1+Inputs!C22)^3 -> 120806.15 | P31: =J31*(1+Inputs!C21)^4-K31*(1+Inputs!C22)^4 -> 124206.49 | Q31: =Inputs!D7*Inputs!D8*Inputs!D10 -> 380362.5 | R31: =Inputs!D17+Inputs!D18 -> 41400 | S31: =Q31*(1+Inputs!D21)^0-R31*(1+Inputs!D22)^0 -> 338962.5 | T31: =Q31*(1+Inputs!D21)^1-R31*(1+Inputs!D22)^1 -> 348717.38 | U31: =Q31*(1+Inputs!D21)^2-R31*(1+Inputs!D22)^2 -> 358748.34 | V31: =Q31*(1+Inputs!D21)^3-R31*(1+Inputs!D22)^3 -> 369063 | W31: =Q31*(1+Inputs!D21)^4-R31*(1+Inputs!D22)^4 -> 379669.2 | X31: =Inputs!F7*Inputs!F8*Inputs!F10 -> 174720 | Y31: =Inputs!F17+Inputs!F18 -> 17500 | Z31: =X31*(1+Inputs!F21)^0-Y31*(1+Inputs!F22)^0 -> 157220 | AA31: =X31*(1+Inputs!F21)^1-Y31*(1+Inputs!F22)^1 -> 161761.6 | AB31: =X31*(1+Inputs!F21)^2-Y31*(1+Inputs!F22)^2 -> 166432.45 | AC31: =X31*(1+Inputs!F21)^3-Y31*(1+Inputs!F22)^3 -> 171236.14 | AD31: =X31*(1+Inputs!F21)^4-Y31*(1+Inputs!F22)^4 -> 176176.37 | AE31: {=NPV(Inputs!B24,E31,F31,G31,H31,I31)-(Inputs!B13+Inputs!B14)} -> 756114.57 | AF31: {=NPV(Inputs!C24,L31,M31,N31,O31,P31)-(Inputs!C13+Inputs!C14)} -> 394481.46 | AG31: {=NPV(Inputs!D24,S31,T31,U31,V31,W31)-(Inputs!D13+Inputs!D14)} -> 1292277.9 | AH31: {=NPV(Inputs!F24,Z31,AA31,AB31,AC31,AD31)-(Inputs!F13+Inputs!F14)} -> 589144.37 | AI31: =MAX(AE31,AF31,AG31,AH31) -> 1292277.9
A32: $25,000 / yr (High tier) | B32: 25000 | C32: =Inputs!B7*Inputs!B8*Inputs!B10 -> 227136 | D32: =25000+Inputs!B18 -> 32000 | E32: =C32*(1+Inputs!B21)^0-D32*(1+Inputs!B22)^0 -> 195136 | F32: =C32*(1+Inputs!B21)^1-D32*(1+Inputs!B22)^1 -> 200670.08 | G32: =C32*(1+Inputs!B21)^2-D32*(1+Inputs!B22)^2 -> 206357.38 | H32: =C32*(1+Inputs!B21)^3-D32*(1+Inputs!B22)^3 -> 212201.99 | I32: =C32*(1+Inputs!B21)^4-D32*(1+Inputs!B22)^4 -> 218208.1 | J32: =Inputs!C7*Inputs!C8*Inputs!C10 -> 131040 | K32: =25000+Inputs!C18 -> 30500 | L32: =J32*(1+Inputs!C21)^0-K32*(1+Inputs!C22)^0 -> 100540 | M32: =J32*(1+Inputs!C21)^1-K32*(1+Inputs!C22)^1 -> 103251.2 | N32: =J32*(1+Inputs!C21)^2-K32*(1+Inputs!C22)^2 -> 106031.54 | O32: =J32*(1+Inputs!C21)^3-K32*(1+Inputs!C22)^3 -> 108882.59 | P32: =J32*(1+Inputs!C21)^4-K32*(1+Inputs!C22)^4 -> 111805.99 | Q32: =Inputs!D7*Inputs!D8*Inputs!D10 -> 380362.5 | R32: =25000+Inputs!D18 -> 34000 | S32: =Q32*(1+Inputs!D21)^0-R32*(1+Inputs!D22)^0 -> 346362.5 | T32: =Q32*(1+Inputs!D21)^1-R32*(1+Inputs!D22)^1 -> 356413.38 | U32: =Q32*(1+Inputs!D21)^2-R32*(1+Inputs!D22)^2 -> 366752.18 | V32: =Q32*(1+Inputs!D21)^3-R32*(1+Inputs!D22)^3 -> 377387 | W32: =Q32*(1+Inputs!D21)^4-R32*(1+Inputs!D22)^4 -> 388326.15 | X32: =Inputs!F7*Inputs!F8*Inputs!F10 -> 174720 | Y32: =25000+Inputs!F18 -> 30500 | Z32: =X32*(1+Inputs!F21)^0-Y32*(1+Inputs!F22)^0 -> 144220 | AA32: =X32*(1+Inputs!F21)^1-Y32*(1+Inputs!F22)^1 -> 148241.6 | AB32: =X32*(1+Inputs!F21)^2-Y32*(1+Inputs!F22)^2 -> 152371.65 | AC32: =X32*(1+Inputs!F21)^3-Y32*(1+Inputs!F22)^3 -> 156612.91 | AD32: =X32*(1+Inputs!F21)^4-Y32*(1+Inputs!F22)^4 -> 160968.21 | AE32: {=NPV(Inputs!B24,E32,F32,G32,H32,I32)-(Inputs!B13+Inputs!B14)} -> 726020.44 | AF32: {=NPV(Inputs!C24,L32,M32,N32,O32,P32)-(Inputs!C13+Inputs!C14)} -> 348910.34 | AG32: {=NPV(Inputs!D24,S32,T32,U32,V32,W32)-(Inputs!D13+Inputs!D14)} -> 1324091.7 | AH32: {=NPV(Inputs!F24,Z32,AA32,AB32,AC32,AD32)-(Inputs!F13+Inputs!F14)} -> 533255.27 | AI32: =MAX(AE32,AF32,AG32,AH32) -> 1324091.7
A33: $40,000 / yr (Enterprise) | B33: 40000 | C33: =Inputs!B7*Inputs!B8*Inputs!B10 -> 227136 | D33: =40000+Inputs!B18 -> 47000 | E33: =C33*(1+Inputs!B21)^0-D33*(1+Inputs!B22)^0 -> 180136 | F33: =C33*(1+Inputs!B21)^1-D33*(1+Inputs!B22)^1 -> 185070.08 | G33: =C33*(1+Inputs!B21)^2-D33*(1+Inputs!B22)^2 -> 190133.38 | H33: =C33*(1+Inputs!B21)^3-D33*(1+Inputs!B22)^3 -> 195329.03 | I33: =C33*(1+Inputs!B21)^4-D33*(1+Inputs!B22)^4 -> 200660.22 | J33: =Inputs!C7*Inputs!C8*Inputs!C10 -> 131040 | K33: =40000+Inputs!C18 -> 45500 | L33: =J33*(1+Inputs!C21)^0-K33*(1+Inputs!C22)^0 -> 85540 | M33: =J33*(1+Inputs!C21)^1-K33*(1+Inputs!C22)^1 -> 87651.2 | N33: =J33*(1+Inputs!C21)^2-K33*(1+Inputs!C22)^2 -> 89807.536 | O33: =J33*(1+Inputs!C21)^3-K33*(1+Inputs!C22)^3 -> 92009.634 | P33: =J33*(1+Inputs!C21)^4-K33*(1+Inputs!C22)^4 -> 94258.11 | Q33: =Inputs!D7*Inputs!D8*Inputs!D10 -> 380362.5 | R33: =40000+Inputs!D18 -> 49000 | S33: =Q33*(1+Inputs!D21)^0-R33*(1+Inputs!D22)^0 -> 331362.5 | T33: =Q33*(1+Inputs!D21)^1-R33*(1+Inputs!D22)^1 -> 340813.38 | U33: =Q33*(1+Inputs!D21)^2-R33*(1+Inputs!D22)^2 -> 350528.18 | V33: =Q33*(1+Inputs!D21)^3-R33*(1+Inputs!D22)^3 -> 360514.04 | W33: =Q33*(1+Inputs!D21)^4-R33*(1+Inputs!D22)^4 -> 370778.28 | X33: =Inputs!F7*Inputs!F8*Inputs!F10 -> 174720 | Y33: =40000+Inputs!F18 -> 45500 | Z33: =X33*(1+Inputs!F21)^0-Y33*(1+Inputs!F22)^0 -> 129220 | AA33: =X33*(1+Inputs!F21)^1-Y33*(1+Inputs!F22)^1 -> 132641.6 | AB33: =X33*(1+Inputs!F21)^2-Y33*(1+Inputs!F22)^2 -> 136147.65 | AC33: =X33*(1+Inputs!F21)^3-Y33*(1+Inputs!F22)^3 -> 139739.95 | AD33: =X33*(1+Inputs!F21)^4-Y33*(1+Inputs!F22)^4 -> 143420.33 | AE33: {=NPV(Inputs!B24,E33,F33,G33,H33,I33)-(Inputs!B13+Inputs!B14)} -> 661533.01 | AF33: {=NPV(Inputs!C24,L33,M33,N33,O33,P33)-(Inputs!C13+Inputs!C14)} -> 284422.91 | AG33: {=NPV(Inputs!D24,S33,T33,U33,V33,W33)-(Inputs!D13+Inputs!D14)} -> 1259604.3 | AH33: {=NPV(Inputs!F24,Z33,AA33,AB33,AC33,AD33)-(Inputs!F13+Inputs!F14)} -> 468767.84 | AI33: =MAX(AE33,AF33,AG33,AH33) -> 1259604.3

Sheet Dashboard
A1: DASHBOARD
B4: UC Berkeley | C4: Stanford University | D4: Arizona State University | E4: SJSU University
B5: ='Economic Metrics'!B4 -> 756114.57 | C5: ='Economic Metrics'!C4 -> 394481.46 | D5: ='Economic Metrics'!D4 -> 1292277.9 | E5: ='Economic Metrics'!E4 -> 589144.37
B6: NPV | C6: NPV | D6: NPV | E6: NPV
A9: KEY METRICS COMPARISON
A10: Metric | B10: UC Berkeley | C10: Stanford University | D10: Arizona State University | E10: SJSU
A11: NPV ($) | B11: ='Economic Metrics'!B4 -> 756114.57 | C11: ='Economic Metrics'!C4 -> 394481.46 | D11: ='Economic Metrics'!D4 -> 1292277.9 | E11: =IFERROR('Economic Metrics'!E4,"N/A") -> 589144.37
A12: IRR | B12: ='Economic Metrics'!B5 -> 2.1485817 | C12: ='Economic Metrics'!C5 -> 1.5339164 | D12: ='Economic Metrics'!D5 -> 2.5343608 | E12: =IFERROR('Economic Metrics'!E5,"N/A") -> 2.1748828
A13: BCR | B13: ='Economic Metrics'!B11 -> 5.2337399 | C13: ='Economic Metrics'!C11 -> 3.848272 | D13: ='Economic Metrics'!D11 -> 5.6213674 | E13: =IFERROR('Economic Metrics'!E11,"N/A") -> 5.5285553
A14: Decision | B14: ='Economic Metrics'!B12 -> ACCEPT | C14: ='Economic Metrics'!C12 -> ACCEPT | D14: ='Economic Metrics'!D12 -> ACCEPT | E14: =IFERROR('Economic Metrics'!E12,"N/A") -> ACCEPT
A19: CHARTS Comparing All Universities
A20: University | B20: NPV ($) | C20: IRR (%) | D20: BCR
A21: UC Berkeley | B21: ='Economic Metrics'!B4 -> 756114.57 | C21: ='Economic Metrics'!B5 -> 2.1485817 | D21: ='Economic Metrics'!B11 -> 5.2337399
A22: Stanford Univ. | B22: ='Economic Metrics'!C4 -> 394481.46 | C22: ='Economic Metrics'!C5 -> 1.5339164 | D22: ='Economic Metrics'!C11 -> 3.848272
A23: Arizona State Univ. | B23: ='Economic Metrics'!D4 -> 1292277.9 | C23: ='Economic Metrics'!D5 -> 2.5343608 | D23: ='Economic Metrics'!D11 -> 5.6213674
A24: SJSU | B24: ='Economic Metrics'!E4 -> 589144.37 | C24: ='Economic Metrics'!E5 -> 2.1748828 | D24: ='Economic Metrics'!E11 -> 5.5285553
A26: SJSU — SAN JOSÉ STATE UNIVERSITY | Full Metrics Detail
A27: Metric | B27: Value | C27: Benchmark vs Others | D27: Status
A28: Support staff (FTE) | B28: =Inputs!F7 -> 8
A29: Annual wage per FTE ($) | B29: =Inputs!F8 -> 62400
A30: Workforce reduction (%) | B30: =Inputs!F10 -> 0.35
A31: Year 0 investment ($) | B31: ='Economic Metrics'!E10 -> 73000
A32: Annual subscription ($) | B32: =Inputs!F17 -> 12000
A33: Annual maintenance ($) | B33: =Inputs!F18 -> 5500
A34: Year 1 labor savings ($) | B34: ='Cash Flows'!C36 -> 174720
A35: Year 1 net cash flow ($) | B35: ='Cash Flows'!F36 -> 157220
A36: 5-yr total benefits ($) | B36: ='Economic Metrics'!E8 -> 927612.21
A37: 5-yr recurring costs ($) | B37: ='Economic Metrics'!E9 -> 94785.645
A38: NPV ($) | B38: ='Economic Metrics'!E4 -> 589144.37 | C38: Rank 3 of 4 universities | D38: =IF('Economic Metrics'!E4>0,"Positive","Negative") -> Positive
A39: IRR | B39: ='Economic Metrics'!E5 -> 2.1748828 | C39: Rank 2 of 4 universities | D39: =IF('Economic Metrics'!E5>Inputs!F24,"IRR > MARR","IRR < MARR") -> IRR > MARR
A40: MARR (hurdle rate) | B40: =Inputs!F24 -> 0.08
A41: IRR − MARR spread | B41: ='Economic Metrics'!E7 -> 2.0948828
A42: Benefit-Cost Ratio | B42: ='Economic Metrics'!E11 -> 5.5285553 | C42: Rank 2 of 4 universities | D42: =IF('Economic Metrics'!E11>1,"BCR > 1.0","BCR < 1.0") -> BCR > 1.0
A43: Discounted payback (yr) | B43: =IFERROR(IF('Cash Flows'!I36>=0,1,IF('Cash Flows'!I37>=0,2,IF('Cash Flows'!I38>=0,3,IF('Cash Flows'!I39>=0,4,IF('Cash Flows'!I40>=0,5,">5"))))),"N/A") -> 1
A44: DECISION | B44: ='Economic Metrics'!E12 -> ACCEPT

Sheet Charts
A1: CHARTS
P3: TABLE
B4: Key Financial Metrics Comparison | M4: University | N4: NPV ($) | O4: IRR (%) | P4: BCR | Q4: Y0 Investment ($) | R4: Total Benefits ($) | S4: Total Costs ($)
B5: Net Present Value (NPV) by University | G5: Internal Rate of Return (IRR) vs MARR Hurdle | M5: UC Berkeley | N5: ='Economic Metrics'!B4 -> 756114.57 | O5: ='Economic Metrics'!B5 -> 2.1485817 | P5: ='Economic Metrics'!B11 -> 5.2337399 | Q5: ='Economic Metrics'!B10 -> 95000 | R5: ='Economic Metrics'!B8 -> 1205895.9 | S5: ='Economic Metrics'!B9+'Economic Metrics'!B10 -> 230408.06
M6: Stanford Univ. | N6: ='Economic Metrics'!C4 -> 394481.46 | O6: ='Economic Metrics'!C5 -> 1.5339164 | P6: ='Economic Metrics'!C11 -> 3.848272 | Q6: ='Economic Metrics'!C10 -> 73000 | R6: ='Economic Metrics'!C8 -> 695709.16 | S6: ='Economic Metrics'!C9+'Economic Metrics'!C10 -> 180784.82
M7: Arizona State Univ. | N7: ='Economic Metrics'!D4 -> 1292277.9 | O7: ='Economic Metrics'!D5 -> 2.5343608 | P7: ='Economic Metrics'!D11 -> 5.6213674 | Q7: ='Economic Metrics'!D10 -> 135000 | R7: ='Economic Metrics'!D8 -> 2019396.2 | S7: ='Economic Metrics'!D9+'Economic Metrics'!D10 -> 359235.75
M8: SJSU | N8: ='Economic Metrics'!E4 -> 589144.37 | O8: ='Economic Metrics'!E5 -> 2.1748828 | P8: ='Economic Metrics'!E11 -> 5.5285553 | Q8: ='Economic Metrics'!E10 -> 73000 | R8: ='Economic Metrics'!E8 -> 927612.21 | S8: ='Economic Metrics'!E9+'Economic Metrics'!E10 -> 167785.64
M10: Year | N10: UC Berkeley | O10: Stanford Univ. | P10: Arizona State Univ. | Q10: SJSU
M11: 0 | N11: ='Cash Flows'!F5 -> -95000 | O11: ='Cash Flows'!F15 -> -73000 | P11: ='Cash Flows'!F25 -> -135000 | Q11: ='Cash Flows'!F35 -> -73000
M12: 1 | N12: ='Cash Flows'!F6 -> 202136 | O12: ='Cash Flows'!F16 -> 111140 | P12: ='Cash Flows'!F26 -> 338962.5 | Q12: ='Cash Flows'!F36 -> 157220
M13: 2 | N13: ='Cash Flows'!F7 -> 207950.08 | O13: ='Cash Flows'!F17 -> 114275.2 | P13: ='Cash Flows'!F27 -> 348717.38 | Q13: ='Cash Flows'!F37 -> 161761.6
M14: 3 | N14: ='Cash Flows'!F8 -> 213928.58 | O14: ='Cash Flows'!F18 -> 117496.5 | P14: ='Cash Flows'!F28 -> 358748.34 | Q14: ='Cash Flows'!F38 -> 166432.45
M15: 4 | N15: ='Cash Flows'!F9 -> 220076.04 | O15: ='Cash Flows'!F19 -> 120806.15 | P15: ='Cash Flows'!F29 -> 369063 | Q15: ='Cash Flows'!F39 -> 171236.14
M16: 5 | N16: ='Cash Flows'!F10 -> 226397.11 | O16: ='Cash Flows'!F20 -> 124206.49 | P16: ='Cash Flows'!F30 -> 379669.2 | Q16: ='Cash Flows'!F40 -> 176176.37
M18: Year | N18: UC Berkeley | O18: Stanford Univ. | P18: Arizona State Univ. | Q18: SJSU
M19: 0 | N19: ='Cash Flows'!I5 -> -95000 | O19: ='Cash Flows'!I15 -> -73000 | P19: ='Cash Flows'!I25 -> -135000 | Q19: ='Cash Flows'!I35 -> -73000
M20: 1 | N20: ='Cash Flows'!I6 -> 92162.963 | O20: ='Cash Flows'!I16 -> 29907.407 | P20: ='Cash Flows'!I26 -> 178854.17 | Q20: ='Cash Flows'!I36 -> 72574.074
M21: 2 | N21: ='Cash Flows'!I7 -> 270446.64 | O21: ='Cash Flows'!I17 -> 127879.97 | P21: ='Cash Flows'!I27 -> 477823.11 | Q21: ='Cash Flows'!I37 -> 211258.57
M22: 3 | N22: ='Cash Flows'!I8 -> 440270.05 | O22: ='Cash Flows'!I18 -> 221152.48 | P22: ='Cash Flows'!I28 -> 762609.11 | Q22: ='Cash Flows'!I38 -> 343378.02
M23: 4 | N23: ='Cash Flows'!I9 -> 602032.5 | O23: ='Cash Flows'!I19 -> 309948.61 | P23: ='Cash Flows'!I29 -> 1033881.4 | Q23: ='Cash Flows'!I39 -> 469241.69
M24: 5 | N24: ='Cash Flows'!I10 -> 756114.57 | O24: ='Cash Flows'!I20 -> 394481.46 | P24: ='Cash Flows'!I30 -> 1292277.9 | Q24: ='Cash Flows'!I40 -> 589144.37
M26: Year | N26: UCB Savings | O26: UCB Costs | P26: SU Savings | Q26: SU Costs | R26: ASU Savings | S26: ASU Costs | T26: SJSU Savings | U26: SJSU Costs
M27: 1 | N27: ='Cash Flows'!C6 -> 227136 | O27: ='Cash Flows'!D6+'Cash Flows'!E6 -> 25000 | P27: ='Cash Flows'!C16 -> 131040 | Q27: ='Cash Flows'!D16+'Cash Flows'!E16 -> 19900 | R27: ='Cash Flows'!C26 -> 380362.5 | S27: ='Cash Flows'!D26+'Cash Flows'!E26 -> 41400 | T27: ='Cash Flows'!C36 -> 174720 | U27: ='Cash Flows'!D36+'Cash Flows'!E36 -> 17500
M28: 2 | N28: ='Cash Flows'!C7 -> 233950.08 | O28: ='Cash Flows'!D7+'Cash Flows'!E7 -> 26000 | P28: ='Cash Flows'!C17 -> 134971.2 | Q28: ='Cash Flows'!D17+'Cash Flows'!E17 -> 20696 | R28: ='Cash Flows'!C27 -> 391773.38 | S28: ='Cash Flows'!D27+'Cash Flows'!E27 -> 43056 | T28: ='Cash Flows'!C37 -> 179961.6 | U28: ='Cash Flows'!D37+'Cash Flows'!E37 -> 18200
B29: Annual Cash Flow & Payback Analysis | M29: 3 | N29: ='Cash Flows'!C8 -> 240968.58 | O29: ='Cash Flows'!D8+'Cash Flows'!E8 -> 27040 | P29: ='Cash Flows'!C18 -> 139020.34 | Q29: ='Cash Flows'!D18+'Cash Flows'!E18 -> 21523.84 | R29: ='Cash Flows'!C28 -> 403526.58 | S29: ='Cash Flows'!D28+'Cash Flows'!E28 -> 44778.24 | T29: ='Cash Flows'!C38 -> 185360.45 | U29: ='Cash Flows'!D38+'Cash Flows'!E38 -> 18928
B30: Net Cash Flow by Year (All Universities) | G30: Cumulative PV (Payback Curve) | M30: 4 | N30: ='Cash Flows'!C9 -> 248197.64 | O30: ='Cash Flows'!D9+'Cash Flows'!E9 -> 28121.6 | P30: ='Cash Flows'!C19 -> 143190.95 | Q30: ='Cash Flows'!D19+'Cash Flows'!E19 -> 22384.794 | R30: ='Cash Flows'!C29 -> 415632.37 | S30: ='Cash Flows'!D29+'Cash Flows'!E29 -> 46569.37 | T30: ='Cash Flows'!C39 -> 190921.26 | U30: ='Cash Flows'!D39+'Cash Flows'!E39 -> 19685.12
M31: 5 | N31: ='Cash Flows'!C10 -> 255643.57 | O31: ='Cash Flows'!D10+'Cash Flows'!E10 -> 29246.464 | P31: ='Cash Flows'!C20 -> 147486.67 | Q31: ='Cash Flows'!D20+'Cash Flows'!E20 -> 23280.185 | R31: ='Cash Flows'!C30 -> 428101.34 | S31: ='Cash Flows'!D30+'Cash Flows'!E30 -> 48432.144 | T31: ='Cash Flows'!C40 -> 196648.9 | U31: ='Cash Flows'!D40+'Cash Flows'!E40 -> 20472.525
M36: Scenario | N36: UC Berkeley | O36: Stanford Univ. | P36: Arizona State Univ. | Q36: SJSU
M37: 25% (Pessimistic) | N37: =Sensitivity!AE7 -> 482230.68 | O37: =Sensitivity!AF7 -> 236471.52 | P37: =Sensitivity!AG7 -> 833631.28 | Q37: =Sensitivity!AH7 -> 378464.46
M38: 35% (Base) | N38: =Sensitivity!AE8 -> 756114.57 | O38: =Sensitivity!AF8 -> 394481.46 | P38: =Sensitivity!AG8 -> 1292277.9 | Q38: =Sensitivity!AH8 -> 589144.37
M39: 45% (Optimistic) | N39: =Sensitivity!AE9 -> 1029998.5 | O39: =Sensitivity!AF9 -> 552491.39 | P39: =Sensitivity!AG9 -> 1750924.5 | Q39: =Sensitivity!AH9 -> 799824.29
M41: MARR | N41: UC Berkeley | O41: Stanford Univ. | P41: Arizona State Univ. | Q41: SJSU
M42: 6% | N42: =Sensitivity!AE14 -> 803885.66 | O42: =Sensitivity!AF14 -> 420710 | P42: =Sensitivity!AG14 -> 1372388.6 | Q42: =Sensitivity!AH14 -> 626312.19
M43: 8% (Base) | N43: =Sensitivity!AE15 -> 756114.57 | O43: =Sensitivity!AF15 -> 394481.46 | P43: =Sensitivity!AG15 -> 1292277.9 | Q43: =Sensitivity!AH15 -> 589144.37
M44: 10% | N44: =Sensitivity!AE16 -> 712236.97 | O44: =Sensitivity!AF16 -> 370390.22 | P44: =Sensitivity!AG16 -> 1218696.5 | Q44: =Sensitivity!AH16 -> 555005.96
M45: 12% | N45: =Sensitivity!AE17 -> 671851.34 | O45: =Sensitivity!AF17 -> 348215.91 | P45: =Sensitivity!AG17 -> 1150971.1 | Q45: =Sensitivity!AH17 -> 523584.56
M47: Setup Scenario | N47: UC Berkeley | O47: Stanford Univ. | P47: Arizona State Univ. | Q47: SJSU
M48: −30% | N48: =Sensitivity!AE22 -> 781614.57 | O48: =Sensitivity!AF22 -> 413981.46 | P48: =Sensitivity!AG22 -> 1328277.9 | Q48: =Sensitivity!AH22 -> 608644.37
M49: Base | N49: =Sensitivity!AE23 -> 756114.57 | O49: =Sensitivity!AF23 -> 394481.46 | P49: =Sensitivity!AG23 -> 1292277.9 | Q49: =Sensitivity!AH23 -> 589144.37
M50: +50% | N50: =Sensitivity!AE24 -> 713614.57 | O50: =Sensitivity!AF24 -> 361981.46 | P50: =Sensitivity!AG24 -> 1232277.9 | Q50: =Sensitivity!AH24 -> 556644.37
...
